Workbook

Sheet Cover
B3: Nestlé Group — FP&A Case Study
B4: FY2021–FY2024 Financial Foundation · FY2025 Budget (Adverse / Base / Favorable) · Budget vs Actual Variance · FY2026 Reforecast & Sensitivity
B5: Independent analysis based exclusively on Nestlé's publicly disclosed financial reports · CHF million unless stated
B8: Prepared by Thanh Vinh Dang | E8: Data as of Nestlé Half-Year Results 2026 (23 July 2026)
B10: FY2025 AT A GLANCE — ACTUAL VS BUDGET
B11: SALES | D11: ORGANIC GROWTH | F11: FX IMPACT ON SALES | H11: UTOP MARGIN
B12: ='3. Variance_Analysis'!C16 -> 89490 | D12: ='3. Variance_Analysis'!C8 -> 0.035 | F12: ='3. Variance_Analysis'!C10 -> -0.057 | H12: ='3. Variance_Analysis'!C37 -> 0.16078891
B13: ="Budget "&TEXT('3. Variance_Analysis'!B16,"#,##0")&" · Var "&TEXT('3. Variance_Analysis'!E16,"+0.0%;-0.0%") -> Budget 94,095 · Var -4.9% | D13: ="Budget "&TEXT('3. Variance_Analysis'!B8,"0.0%")&" · Var "&TEXT('3. Variance_Analysis'!D8,"+0;-0")&" bps" -> Budget 3.0% · Var +50 bps | F13: ="Budget "&TEXT('3. Variance_Analysis'!B10,"0.0%")&" · Var "&TEXT('3. Variance_Analysis'!D10,"+0;-0")&" bps" -> Budget 0.0% · Var -570 bps | H13: ="Budget "&TEXT('3. Variance_Analysis'!B37,"0.0%")&" · Var "&TEXT('3. Variance_Analysis'!D37,"+0;-0")&" bps" -> Budget 16.6% · Var -52 bps
B16: NET PROFIT | D16: BASIC EPS (CHF) | F16: OPERATING CASH FLOW | H16: FREE CASH FLOW (REPORTED)
B17: ='3. Variance_Analysis'!C35 -> 9033 | D17: ='3. Variance_Analysis'!C43 -> 3.51 | F17: ='3. Variance_Analysis'!C62 -> 15904 | H17: ='3. Variance_Analysis'!C90 -> 9154
B18: ="Budget "&TEXT('3. Variance_Analysis'!B35,"#,##0")&" · Var "&TEXT('3. Variance_Analysis'!E35,"+0.0%;-0.0%") -> Budget 10,608 · Var -14.8% | D18: ="Budget "&TEXT('3. Variance_Analysis'!B43,"0.00")&" · Var "&TEXT('3. Variance_Analysis'!E43,"+0.0%;-0.0%") -> Budget 4.15 · Var -15.5% | F18: ="Budget "&TEXT('3. Variance_Analysis'!B62,"#,##0")&" · Var "&TEXT('3. Variance_Analysis'!E62,"+0.0%;-0.0%") -> Budget 15,666 · Var +1.5% | H18: ="Budget "&TEXT('3. Variance_Analysis'!B90,"#,##0")&" · Var "&TEXT('3. Variance_Analysis'!E90,"+0.0%;-0.0%") -> Budget 9,455 · Var -3.2%
B21: KEY MESSAGE
B22: FY2025 was a currency story, not an execution miss. Organic growth beat the Budget (3.5% vs 3.0%), but with the opposite mix to plan — pricing (+2.8%) carried growth while volume (RIG +0.8%) disappointed. A -5.7% FX headwind against a flat Budget assumption turned a planned +3.0% reported sales growth into a -2.0% decline. UTOP margin of 16.1% still landed within Nestlé's guidance of "at or above 16.0%". The FY2026 reforecast uses Nestlé's latest guidance where it exists (FX about -3%, H2 margin similar to H1) and judgement elsewhere: 3.5% organic growth, a 16.5% UTOP margin and about CHF 10.7bn of free cash flow, but net profit down about 11% after a CHF 1.3bn write-down. Each 10 bps of COGS moves net profit as much as 0.8 pp of FX.
B24: CONTENTS
B25: Step | C25: Sheet | E25: What it contains
B26: — | C26: README | E26: Workbook guide, data sources, conventions and key caveats
B27: 1 | C27: 1. Segment_Data | E27: Sales & UTOP by reporting segment, FY2021–FY2024, with RIG/Pricing bridge
B28: 1 | C28: 1. Category_Data | E28: Sales & UTOP by product category, FY2021–FY2024
B29: 1 | C29: 1. Income_Statement | E29: Full consolidated Income Statement, FY2021–FY2024
B30: 1 | C30: 1. Cash_Flow_Statement | E30: Full consolidated Statement of Cash Flows, FY2021–FY2024
B31: 2 | C31: 2. Assumptions_FY2025 | E31: ~40 FY2025 drivers under Adverse / Base / Favorable scenarios, each sourced or explained
B32: 2 | C32: 2. Budget_FY2025_PL_CF | E32: Full-detail FY2025 Budget (P&L + Cash Flow), three scenarios vs FY2024 Actual
B33: 3 | C33: 3. Variance_Analysis | E33: Actual vs Base: RIG/Pricing/FX bridge, P&L & CF variance, scenario range, driver backtest
B34: 4 | C34: 4. Assumptions_FY2026 | E34: FY2026 drivers vs FY2025 Budget and Actual: Nestlé guidance where given, judgement elsewhere
B35: 4 | C35: 4. Reforecast_FY2026 | E35: FY2026 Reforecast vs FY2025 Actual (P&L + Cash Flow), checked against FY2026 guidance
B36: 4 | C36: 4. Sensitivity_FY2026 | E36: Sensitivity of FY2026 net profit, EPS and FCF to FX and COGS (one-way and two-way)
B38: Cell conventions: | C38: Blue = sourced input | E38: Black = formula | F38: Green = link to another sheet | H38: Yellow = budget assumption
B40: Disclaimer: this is an independent portfolio analysis. It is not prepared by, affiliated with, or endorsed by Nestlé S.A. All actual figures are taken from Nestlé's published Full-Year Results press releases and Financial Statements; budget figures are the author's own assumptions. "Nestlé" is a registered trademark of Société des Produits Nestlé S.A.

Sheet README
A1: Nestlé FP&A Case Study — Data Foundation
A3: Purpose
A4: This workbook covers the Excel steps of an end-to-end FP&A portfolio project: a Data Foundation built on Nestlé's real, publicly disclosed segment and product-category financials (FY2021–FY2024), a driver-based FY2025 Budget built under Adverse / Base / Favorable scenarios, a Variance Analysis of that Budget against Nestlé's actual FY2025 results, and a full-year FY2026 Reforecast with a Sensitivity Analysis on the two drivers that missed most in FY2025 (FX and COGS). Step 5, the Power BI dashboard, lives in the powerbi/ folder of the repository.
A6: Sheets in this workbook
A7: • 1. Segment_Data — Sales & Underlying Trading Operating Profit (UTOP) by reporting segment (5 geographic Zones + Nespresso + Nestlé Health Science + Other Businesses), FY2021–FY2024, with the organic growth bridge (RIG / Pricing / Net M&A / FX) for FY2022 and FY2024.
A8: • 1. Category_Data — Sales & UTOP by product category (7 categories: Powdered & liquid beverages, Water, Milk products & ice cream, Nutrition & Health Science, Prepared dishes & cooking aids, Confectionery, PetCare), FY2021–FY2024.
A9: • 1. Income_Statement — Full consolidated Income Statement, line by line (Sales, Other revenue, COGS, Distribution expenses, Marketing & admin expenses, R&D costs, Other trading/operating income & expenses, Financial income/expense, Income from associates & JVs, Taxes, NCI), FY2021–FY2024, with every subtotal (UTOP, Trading Operating Profit, Operating Profit, PBT, Profit for the Year, Net Profit) computed by formula from the disclosed line items above it — never hardcoded.
A10: • 1. Cash_Flow_Statement — Full consolidated Statement of Cash Flows, line by line across Operating, Investing and Financing activities plus the cash reconciliation and a Free Cash Flow memo, FY2021–FY2024, with every subtotal (Cash Generated from Operations, Operating/Investing/Financing Cash Flow) computed by formula.
A11: • 2. Assumptions_FY2025 — ~40 line-item FY2025 budget drivers covering the full Income Statement and Cash Flow Statement, in three columns: Adverse / Base / Favorable. Base follows Nestlé's own FY2025 guidance where available, or an explicit own-assumption with rationale where not. Adverse and Favorable flex ten key drivers (RIG, FX, COGS %, Marketing & Admin %, other trading items, net financial expense, associates income, tax rate, working capital, capex) using ranges sized from FY2021–FY2024 history; all other drivers are held at Base. Yellow cells are the editable levers.
A12: • 2. Budget_FY2025_PL_CF — Full-detail FY2025 Budget under the Adverse, Base and Favorable scenarios, side by side with FY2024 Actual, built at the same line-item level as 1. Income_Statement and 1. Cash_Flow_Statement and fully driven by 2. Assumptions_FY2025. Built from guidance disclosed BEFORE FY2025 actual results were known; the Base scenario is the plan that Step 3 (Variance Analysis) measures against.
A13: • 3. Variance_Analysis — FY2025 Actual versus the Base Budget: a Group Sales Growth Bridge decomposing the variance into RIG (Real Internal Growth), Pricing, Net M&A and FX — the same framework Nestlé uses in its own disclosures — a full line-item Income Statement and Cash Flow variance (CHF m and %), where Actual landed versus the Adverse / Base / Favorable scenarios, a backtest of each flexed driver against its scenario range, and written commentary. All FY2025 Actual figures are hardcoded inputs (blue), sourced from Nestlé's FY2025 Full-Year Results press release and Financial Statements, cited in Data sources below.
A14: • 4. Assumptions_FY2026 — every FY2026 driver next to the FY2025 Budget (Base), the FY2025 Actual and the H1-2026 actual. Numbers Nestlé has guided or already reported are used as published, with the source (latest: Half-Year Results 2026, 23-Jul-2026 — FX about -3%, organic growth 3%–4% with RIG accelerating, H2 UTOP margin broadly similar to H1, free cash flow above CHF 9bn, the CHF 1.3bn held-for-sale write-down). Every other driver is a judgement informed by the FY2025 variance, labelled [Judgement], never a copy of the FY2025 figure.
... A34: • 1. Income_Statement / 1. Cash_Flow_Statement sheets: sourced from Nestlé's full Financial Statements documents (not the condensed press releases used for 1. Segment_Data/1. Category_Data) for full line-item detail. FY2022's 'Cash generated from operations' section reflects the "Decrease/(increase) in working capital" and "Variation of other operating assets and liabilities" lines as disclosed that year. The 'Free Cash Flow (derived)' row will not tie exactly to Nestlé's own reported FCF figure — this is flagged on the 1. Cash_Flow_Statement sheet, not hidden.

Sheet 1. Segment_Data
A1: Nestlé — Segment Sales & Profitability, FY2021–FY2024 (CHF m unless %)
A3: Segment | B3: FY2021 Sales | C3: FY2022 Sales | D3: FY2023 Sales | E3: FY2024 Sales | F3: FY22 Sales YoY | G3: FY23 Sales YoY | H3: FY24 Sales YoY | I3: FY2021 UTOP | J3: FY2022 UTOP | K3: FY2023 UTOP | L3: FY2024 UTOP | M3: FY2021 UTOP Margin | N3: FY2022 UTOP Margin | O3: FY2023 UTOP Margin | P3: FY2024 UTOP Margin | Q3: FY22 RIG | R3: FY22 Pricing | S3: FY22 Organic Gr. | T3: FY22 Net M&A | U3: FY22 FX | V3: FY24 RIG | W3: FY24 Pricing | X3: FY24 Organic Gr. | Y3: FY24 Net M&A | Z3: FY24 FX
A4: Zone North America | B4: 23693 | C4: 26328 | D4: 25995 | E4: 25336 | F4: =IFERROR(C4/B4-1,"") -> 0.11121428 | G4: =IFERROR(D4/C4-1,"") -> -0.012648131 | H4: =IFERROR(E4/D4-1,"") -> -0.025351029 | I4: 4804 | J4: 5528 | K4: 5768 | L4: 5640 | M4: =IFERROR(I4/B4,"") -> 0.20276031 | N4: =IFERROR(J4/C4,"") -> 0.20996658 | O4: =IFERROR(K4/D4,"") -> 0.22188882 | P4: =IFERROR(L4/E4,"") -> 0.22260815 | Q4: -0.013 | R4: 0.116 | S4: 0.103 | T4: -0.038 | U4: 0.047 | V4: -0.008 | W4: 0.004 | X4: -0.005 | Y4: -0.001 | Z4: -0.02
A5: Zone Europe | B5: 18794 | C5: 19128 | D5: 19098 | E5: 18910 | F5: =IFERROR(C5/B5-1,"") -> 0.017771629 | G5: =IFERROR(D5/C5-1,"") -> -0.0015683814 | H5: =IFERROR(E5/D5-1,"") -> -0.0098439627 | I5: 3439 | J5: 3138 | K5: 3127 | L5: 3192 | M5: =IFERROR(I5/B5,"") -> 0.18298393 | N5: =IFERROR(J5/C5,"") -> 0.1640527 | O5: =IFERROR(K5/D5,"") -> 0.16373442 | P5: =IFERROR(L5/E5,"") -> 0.16879958 | Q5: 0.009 | R5: 0.064 | S5: 0.072 | T5: 0.021 | U5: -0.076 | V5: 0.008 | W5: 0.025 | X5: 0.033 | Y5: -0.019 | Z5: -0.025
A6: Zone AOA | B6: 17894 | C6: 18484 | D6: 17519 | E6: 16793 | F6: =IFERROR(C6/B6-1,"") -> 0.032971946 | G6: =IFERROR(D6/C6-1,"") -> -0.052207314 | H6: =IFERROR(E6/D6-1,"") -> -0.041440722 | I6: 4288 | J6: 4237 | K6: 4109 | L6: 3916 | M6: =IFERROR(I6/B6,"") -> 0.2396334 | N6: =IFERROR(J6/C6,"") -> 0.22922528 | O6: =IFERROR(K6/D6,"") -> 0.23454535 | P6: =IFERROR(L6/E6,"") -> 0.2331924 | Q6: 0.001 | R6: 0.081 | S6: 0.082 | T6: -0.001 | U6: -0.049 | V6: 0.006 | W6: 0.028 | X6: 0.034 | Y6: 0 | Z6: -0.075
A7: Zone Latin America | B7: 10086 | C7: 11819 | D7: 12196 | E7: 11933 | F7: =IFERROR(C7/B7-1,"") -> 0.17182233 | G7: =IFERROR(D7/C7-1,"") -> 0.031897792 | H7: =IFERROR(E7/D7-1,"") -> -0.021564447 | I7: 2208 | J7: 2501 | K7: 2520 | L7: 2429 | M7: =IFERROR(I7/B7,"") -> 0.21891731 | N7: =IFERROR(J7/C7,"") -> 0.21160843 | O7: =IFERROR(K7/D7,"") -> 0.20662512 | P7: =IFERROR(L7/E7,"") -> 0.20355317 | Q7: 0.015 | R7: 0.116 | S7: 0.131 | T7: 0.001 | U7: 0.04 | V7: -0.003 | W7: 0.027 | X7: 0.025 | Y7: 0.004 | Z7: -0.049
A8: Zone Greater China | B8: 5175 | C8: 5351 | D8: 5037 | E8: 4973 | F8: =IFERROR(C8/B8-1,"") -> 0.034009662 | G8: =IFERROR(D8/C8-1,"") -> -0.05868062 | H8: =IFERROR(E8/D8-1,"") -> -0.012705976 | I8: 700 | J8: 862 | K8: 832 | L8: 803 | M8: =IFERROR(I8/B8,"") -> 0.1352657 | N8: =IFERROR(J8/C8,"") -> 0.16109138 | O8: =IFERROR(K8/D8,"") -> 0.16517769 | P8: =IFERROR(L8/E8,"") -> 0.16147195 | Q8: 0.01 | R8: 0.025 | S8: 0.035 | T8: 0 | U8: -0.001 | V8: 0.043 | W8: -0.021 | X8: 0.021 | Y8: 0.001 | Z8: -0.035
A9: Nestlé Health Science | B9: 4822 | C9: 6602 | D9: 6498 | E9: 6739 | F9: =IFERROR(C9/B9-1,"") -> 0.36914144 | G9: =IFERROR(D9/C9-1,"") -> -0.015752802 | H9: =IFERROR(E9/D9-1,"") -> 0.037088335 | I9: 654 | J9: 899 | K9: 777 | L9: 943 | M9: =IFERROR(I9/B9,"") -> 0.13562837 | N9: =IFERROR(J9/C9,"") -> 0.13617086 | O9: =IFERROR(K9/D9,"") -> 0.11957525 | P9: =IFERROR(L9/E9,"") -> 0.13993174 | Q9: 0.006 | R9: 0.034 | S9: 0.04 | T9: 0.315 | U9: 0.015 | V9: 0.055 | W9: 0.007 | X9: 0.062 | Y9: 0.002 | Z9: -0.028
A10: Nespresso | B10: 6418 | C10: 6448 | D10: 6372 | E10: 6378 | F10: =IFERROR(C10/B10-1,"") -> 0.0046743534 | G10: =IFERROR(D10/C10-1,"") -> -0.0117866 | H10: =IFERROR(E10/D10-1,"") -> 0.00094161959 | I10: 1475 | J10: 1388 | K10: 1291 | L10: 1278 | M10: =IFERROR(I10/B10,"") -> 0.22982237 | N10: =IFERROR(J10/C10,"") -> 0.21526055 | O10: =IFERROR(K10/D10,"") -> 0.20260515 | P10: =IFERROR(L10/E10,"") -> 0.20037629 | Q10: -0.017 | R10: 0.052 | S10: 0.035 | T10: -0.003 | U10: -0.027 | V10: 0.016 | W10: 0.006 | X10: 0.022 | Y10: 0.002 | Z10: -0.024
A11: Other Businesses | B11: 206 | C11: 264 | D11: 283 | E11: 292 | F11: =IFERROR(C11/B11-1,"") -> 0.2815534 | G11: =IFERROR(D11/C11-1,"") -> 0.071969697 | H11: =IFERROR(E11/D11-1,"") -> 0.03180212 | I11: -32 | J11: -17 | K11: -12 | L11: -13 | M11: =IFERROR(I11/B11,"") -> -0.15533981 | N11: =IFERROR(J11/C11,"") -> -0.064393939 | O11: =IFERROR(K11/D11,"") -> -0.042402827 | P11: =IFERROR(L11/E11,"") -> -0.044520548 | Q11: 0.252 | R11: 0.032 | S11: 0.284 | T11: 0 | U11: -0.001 | V11: 0.053 | W11: 0.013 | X11: 0.066 | Y11: 0 | Z11: -0.027
A12: Total Group | B12: =SUM(B4:B11) -> 87088 | C12: =SUM(C4:C11) -> 94424 | D12: =SUM(D4:D11) -> 92998 | E12: =SUM(E4:E11) -> 91354 | F12: =IFERROR(C12/B12-1,"") -> 0.084236634 | G12: =IFERROR(D12/C12-1,"") -> -0.015102093 | H12: =IFERROR(E12/D12-1,"") -> -0.0176778 | I12: 15119 | J12: 16103 | K12: 16053 | L12: 15704 | M12: =IFERROR(I12/B12,"") -> 0.17360601 | N12: =IFERROR(J12/C12,"") -> 0.17053927 | O12: =IFERROR(K12/D12,"") -> 0.17261662 | P12: =IFERROR(L12/E12,"") -> 0.17190271 | Q12: 0.001 | R12: 0.082 | S12: 0.083 | T12: 0.011 | U12: -0.009 | V12: 0.008 | W12: 0.015 | X12: 0.022 | Y12: -0.003 | Z12: -0.037
A14: Source: Nestlé Full-Year Results press releases 2022 and 2024 (see README for links). FY21/FY22 RIG/Pricing/OG/M&A/FX exclude Russia.
A15: Note: Segment UTOP figures sum to more than the Group Total UTOP shown above — this is expected. Nestlé's Group total nets off unallocated central costs and eliminations that are not broken out by segment in the summary disclosure, so the Total row uses the company's reported Group figure directly rather than a SUM of segments.

Sheet 1. Category_Data
A1: Nestlé — Sales & Profitability by Product Category, FY2021–FY2024 (CHF m unless %)
A3: Category | B3: FY2021 Sales | C3: FY2022 Sales | D3: FY2023 Sales | E3: FY2024 Sales | F3: FY22 Sales YoY | G3: FY23 Sales YoY | H3: FY24 Sales YoY | I3: FY2021 UTOP | J3: FY2022 UTOP | K3: FY2023 UTOP | L3: FY2024 UTOP | M3: FY2021 UTOP Margin | N3: FY2022 UTOP Margin | O3: FY2023 UTOP Margin | P3: FY2024 UTOP Margin | Q3: FY22 RIG | R3: FY22 Pricing | S3: FY22 Organic Gr. | T3: FY24 RIG | U3: FY24 Pricing | V3: FY24 Organic Gr.
A4: Powdered & liquid beverages | B4: 23975 | C4: 25218 | D4: 24786 | E4: 24598 | F4: =IFERROR(C4/B4-1,"") -> 0.051845673 | G4: =IFERROR(D4/C4-1,"") -> -0.017130621 | H4: =IFERROR(E4/D4-1,"") -> -0.007584927 | I4: 5631 | J4: 5593 | K4: 5130 | L4: 4920 | M4: =IFERROR(I4/B4,"") -> 0.23486966 | N4: =IFERROR(J4/C4,"") -> 0.22178603 | O4: =IFERROR(K4/D4,"") -> 0.20697168 | P4: =IFERROR(L4/E4,"") -> 0.20001626 | Q4: 0.002 | R4: 0.078 | S4: 0.08 | T4: 0.016 | U4: 0.017 | V4: 0.033
A5: Water | B5: 4040 | C5: 3536 | D5: 3320 | E5: 3180 | F5: =IFERROR(C5/B5-1,"") -> -0.12475248 | G5: =IFERROR(D5/C5-1,"") -> -0.061085973 | H5: =IFERROR(E5/D5-1,"") -> -0.042168675 | I5: 364 | J5: 277 | K5: 351 | L5: 297 | M5: =IFERROR(I5/B5,"") -> 0.09009901 | N5: =IFERROR(J5/C5,"") -> 0.078337104 | O5: =IFERROR(K5/D5,"") -> 0.10572289 | P5: =IFERROR(L5/E5,"") -> 0.093396226 | Q5: 0.022 | R5: 0.089 | S5: 0.11 | T5: -0.01 | U5: 0.032 | V5: 0.023
A6: Milk products & ice cream | B6: 10700 | C6: 11289 | D6: 10981 | E6: 10397 | F6: =IFERROR(C6/B6-1,"") -> 0.055046729 | G6: =IFERROR(D6/C6-1,"") -> -0.027283196 | H6: =IFERROR(E6/D6-1,"") -> -0.05318277 | I6: 2707 | J6: 2568 | K6: 2688 | L6: 2442 | M6: =IFERROR(I6/B6,"") -> 0.25299065 | N6: =IFERROR(J6/C6,"") -> 0.22747808 | O6: =IFERROR(K6/D6,"") -> 0.24478645 | P6: =IFERROR(L6/E6,"") -> 0.23487544 | Q6: -0.043 | R6: 0.096 | S6: 0.054 | T6: -0.007 | U6: 0.001 | V6: -0.006
A7: Nutrition & Health Science | B7: 13157 | C7: 15678 | D7: 15278 | E7: 15137 | F7: =IFERROR(C7/B7-1,"") -> 0.19160903 | G7: =IFERROR(D7/C7-1,"") -> -0.025513458 | H7: =IFERROR(E7/D7-1,"") -> -0.0092289567 | I7: 2307 | J7: 2990 | K7: 2831 | L7: 3006 | M7: =IFERROR(I7/B7,"") -> 0.17534392 | N7: =IFERROR(J7/C7,"") -> 0.1907131 | O7: =IFERROR(K7/D7,"") -> 0.18529912 | P7: =IFERROR(L7/E7,"") -> 0.19858625 | Q7: 0.017 | R7: 0.057 | S7: 0.074 | T7: 0.019 | U7: 0.009 | V7: 0.028
A8: Prepared dishes & cooking aids | B8: 12146 | C8: 12484 | D8: 11666 | E8: 10711 | F8: =IFERROR(C8/B8-1,"") -> 0.027828092 | G8: =IFERROR(D8/C8-1,"") -> -0.065523871 | H8: =IFERROR(E8/D8-1,"") -> -0.081861821 | I8: 2040 | J8: 2038 | K8: 2136 | L8: 2137 | M8: =IFERROR(I8/B8,"") -> 0.16795653 | N8: =IFERROR(J8/C8,"") -> 0.16324896 | O8: =IFERROR(K8/D8,"") -> 0.18309618 | P8: =IFERROR(L8/E8,"") -> 0.19951452 | Q8: -0.069 | R8: 0.1 | S8: 0.031 | T8: -0.022 | U8: 0.005 | V8: -0.017
A9: Confectionery | B9: 7514 | C9: 8118 | D9: 8107 | E9: 8449 | F9: =IFERROR(C9/B9-1,"") -> 0.080383285 | G9: =IFERROR(D9/C9-1,"") -> -0.0013550136 | H9: =IFERROR(E9/D9-1,"") -> 0.042185765 | I9: 1205 | J9: 1364 | K9: 1364 | L9: 1299 | M9: =IFERROR(I9/B9,"") -> 0.16036731 | N9: =IFERROR(J9/C9,"") -> 0.16802168 | O9: =IFERROR(K9/D9,"") -> 0.16824966 | P9: =IFERROR(L9/E9,"") -> 0.15374601 | Q9: 0.048 | R9: 0.047 | S9: 0.094 | T9: -0.002 | U9: 0.064 | V9: 0.062
A10: PetCare | B10: 15556 | C10: 18101 | D10: 18860 | E10: 18882 | F10: =IFERROR(C10/B10-1,"") -> 0.16360247 | G10: =IFERROR(D10/C10-1,"") -> 0.041931385 | H10: =IFERROR(E10/D10-1,"") -> 0.0011664899 | I10: 3282 | J10: 3706 | K10: 3912 | L10: 4087 | M10: =IFERROR(I10/B10,"") -> 0.21097969 | N10: =IFERROR(J10/C10,"") -> 0.20474007 | O10: =IFERROR(K10/D10,"") -> 0.20742312 | P10: =IFERROR(L10/E10,"") -> 0.21644953 | Q10: 0.043 | R10: 0.102 | S10: 0.145 | T10: 0.021 | U10: 0.006 | V10: 0.027
A11: Total Group | B11: =SUM(B4:B10) -> 87088 | C11: =SUM(C4:C10) -> 94424 | D11: =SUM(D4:D10) -> 92998 | E11: =SUM(E4:E10) -> 91354 | F11: =IFERROR(C11/B11-1,"") -> 0.084236634 | G11: =IFERROR(D11/C11-1,"") -> -0.015102093 | H11: =IFERROR(E11/D11-1,"") -> -0.0176778 | I11: 15119 | J11: 16103 | K11: 16053 | L11: 15704 | M11: =IFERROR(I11/B11,"") -> 0.17360601 | N11: =IFERROR(J11/C11,"") -> 0.17053927 | O11: =IFERROR(K11/D11,"") -> 0.17261662 | P11: =IFERROR(L11/E11,"") -> 0.17190271
A13: Source: Nestlé Full-Year Results press releases 2022 and 2024 (see README for links).
A14: Note: as with the segment view, category UTOP figures sum to more than Group Total UTOP because unallocated central costs are not broken out by category. The Total row uses Nestlé's reported Group figure directly.

Sheet 1. Income_Statement
A1: Nestlé Group — Consolidated Income Statement, FY2021–FY2024 (CHF million unless per-share)
A3: Line Item | B3: FY2021 | C3: FY2022 | D3: FY2023 | E3: FY2024
A4: Sales | B4: 87088 | C4: 94424 | D4: 92998 | E4: 91354
A5: Other revenue | B5: 382 | C5: 356 | D5: 353 | E5: 366
A6: Cost of goods sold | B6: -45468 | C6: -51745 | D6: -50328 | E6: -48670
A7: Distribution expenses | B7: -7919 | C7: -8386 | D7: -7765 | E7: -7567
A8: Marketing and administration expenses | B8: -17294 | C8: -16850 | D8: -17549 | E8: -18112
A9: Research and development costs | B9: -1670 | C9: -1696 | D9: -1656 | E9: -1667
A10: Underlying Trading Operating Profit (UTOP)* | B10: =SUM(B4:B9) -> 15119 | C10: =SUM(C4:C9) -> 16103 | D10: =SUM(D4:D9) -> 16053 | E10: =SUM(E4:E9) -> 15704
A11: Other trading income | B11: 171 | C11: 107 | D11: 132 | E11: 124
A12: Other trading expenses | B12: -3131 | C12: -3015 | D12: -1665 | E12: -1195
A13: Trading Operating Profit | B13: =B10+B11+B12 -> 12159 | C13: =C10+C11+C12 -> 13195 | D13: =D10+D11+D12 -> 14520 | E13: =E10+E11+E12 -> 14633
A14: Other operating income | B14: 698 | C14: 340 | D14: 298 | E14: 474
A15: Other operating expenses | B15: -1178 | C15: -1209 | D15: -755 | E15: -383
A16: Operating Profit | B16: =B13+B14+B15 -> 11679 | C16: =C13+C14+C15 -> 12326 | D16: =D13+D14+D15 -> 14063 | E16: =E13+E14+E15 -> 14724
A17: Financial income | B17: 80 | C17: 210 | D17: 284 | E17: 358
A18: Financial expense | B18: -953 | C18: -1250 | D18: -1644 | E18: -1843
A19: Net Financial Income/(Expense) | B19: =B17+B18 -> -873 | C19: =C17+C18 -> -1040 | D19: =D17+D18 -> -1360 | E19: =E17+E18 -> -1485
A20: Profit Before Taxes, Associates and Joint Ventures | B20: =B16+B19 -> 10806 | C20: =C16+C19 -> 11286 | D20: =D16+D19 -> 12703 | E20: =E16+E19 -> 13239
A21: Income from associates and joint ventures | B21: 8651 | C21: 1040 | D21: 1120 | E21: 1249
A22: Taxes | B22: -2261 | C22: -2730 | D22: -2314 | E22: -3314
A23: Profit for the Year | B23: =B20+B21+B22 -> 17196 | C23: =C20+C21+C22 -> 9596 | D23: =D20+D21+D22 -> 11509 | E23: =E20+E21+E22 -> 11174
A24: Of which: non-controlling interests | B24: 291 | C24: 326 | D24: 300 | E24: 290
A25: Net Profit (attributable to shareholders of the parent) | B25: =B23-B24 -> 16905 | C25: =C23-C24 -> 9270 | D25: =D23-D24 -> 11209 | E25: =E23-E24 -> 10884
A27: UTOP Margin | B27: =IFERROR(B10/B4,"") -> 0.17360601 | C27: =IFERROR(C10/C4,"") -> 0.17053927 | D27: =IFERROR(D10/D4,"") -> 0.17261662 | E27: =IFERROR(E10/E4,"") -> 0.17190271
A28: Trading Operating Profit Margin | B28: =IFERROR(B13/B4,"") -> 0.1396174 | C28: =IFERROR(C13/C4,"") -> 0.13974201 | D28: =IFERROR(D13/D4,"") -> 0.15613239 | E28: =IFERROR(E13/E4,"") -> 0.16017908
A29: Operating Profit Margin | B29: =IFERROR(B16/B4,"") -> 0.13410573 | C29: =IFERROR(C16/C4,"") -> 0.13053885 | D29: =IFERROR(D16/D4,"") -> 0.15121831 | E29: =IFERROR(E16/E4,"") -> 0.16117521
A30: Net Profit Margin | B30: =IFERROR(B25/B4,"") -> 0.194114 | C30: =IFERROR(C25/C4,"") -> 0.098174193 | D30: =IFERROR(D25/D4,"") -> 0.12052947 | E30: =IFERROR(E25/E4,"") -> 0.11914092
A31: Effective Tax Rate (Taxes ÷ PBT) | B31: =IFERROR(-B22/B20,"") -> 0.20923561 | C31: =IFERROR(-C22/C20,"") -> 0.24189261 | D31: =IFERROR(-D22/D20,"") -> 0.18216169 | E31: =IFERROR(-E22/E20,"") -> 0.25032102
A33: Basic earnings per share (CHF) | B33: 6.06 | C33: 3.42 | D33: 4.24 | E33: 4.19
A34: Diluted earnings per share (CHF) | B34: 6.06 | C34: 3.42 | D34: 4.23 | E34: 4.19
A36: * "Underlying Trading Operating Profit" (UTOP) is Nestlé's own key profitability KPI. It is not printed as an explicit line in the statutory income statement, but is fully derivable as Sales + Other revenue − Cost of goods sold − Distribution expenses − Marketing & administration expenses − Research & development costs (computed here as a formula, not hardcoded) — it ties exactly to the UTOP figures Nestlé discloses separately (e.g. FY2024: CHF 15,704m, 17.2% margin).
A37: Sources: Nestlé Financial Statements 2024 (published 13-Feb-2025) for FY2024 and FY2023 — https://www.nestle.com/sites/default/files/2025-02/2024-financial-statements-en.pdf ; Nestlé Financial Statements 2022 (published 16-Feb-2023) for FY2022 and FY2021 — https://www.nestle.com/sites/default/files/2023-02/2022-financial-statements-en.pdf
A38: Shaded rows are subtotals computed by formula from the line items above them — never hardcoded — so every number here is traceable back to a disclosed line item.
A39: FY2021's unusually high Net Profit (CHF 16,905m) and 'Income from associates and joint ventures' (CHF 8,651m) reflect the one-off gain on Nestlé's disposal of part of its L'Oréal stake in 2021, not a recurring item.

Sheet 1. Cash_Flow_Statement
A1: Nestlé Group — Consolidated Statement of Cash Flows, FY2021–FY2024 (CHF million)
A3: Line Item | B3: FY2021 | C3: FY2022 | D3: FY2023 | E3: FY2024
A4: OPERATING ACTIVITIES
A5: Operating Profit (linked from Income_Statement) | B5: ='1. Income_Statement'!B16 -> 11679 | C5: ='1. Income_Statement'!C16 -> 12326 | D5: ='1. Income_Statement'!D16 -> 14063 | E5: ='1. Income_Statement'!E16 -> 14724
A6: Depreciation and amortization | B6: 3440 | C6: 3541 | D6: 3458 | E6: 3582
A7: Impairment | B7: 2614 | C7: 2726 | D7: 647 | E7: 580
A8: Net result on disposal of businesses | B8: -235 | C8: 79 | D8: 221 | E8: 62
A9: Other non-cash items of income and expense | B9: -253 | C9: 216 | D9: 82 | E9: -229
A10: Cash Flow Before Changes in Operating Assets and Liabilities | B10: =SUM(B5:B9) -> 17245 | C10: =SUM(C5:C9) -> 18888 | D10: =SUM(D5:D9) -> 18471 | E10: =SUM(E5:E9) -> 18719
A11: Decrease/(increase) in working capital | B11: -173 | C11: -3133 | D11: 1134 | E11: 1208
A12: Variation of other operating assets and liabilities | B12: -427 | C12: -514 | D12: -425 | E12: -334
A13: Cash Generated from Operations | B13: =B10+B11+B12 -> 16645 | C13: =C10+C11+C12 -> 15241 | D13: =D10+D11+D12 -> 19180 | E13: =E10+E11+E12 -> 19593
A14: Interest paid | B14: -753 | C14: -953 | D14: -1330 | E14: -1539
A15: Interest and dividends received | B15: 43 | C15: 118 | D15: 193 | E15: 273
A16: Taxes paid | B16: -2722 | C16: -3107 | D16: -2801 | E16: -2411
A17: Dividends and interest from associates and joint ventures | B17: 651 | C17: 608 | D17: 699 | E17: 759
A18: Operating Cash Flow | B18: =B13+B14+B15+B16+B17 -> 13864 | C18: =C13+C14+C15+C16+C17 -> 11907 | D18: =D13+D14+D15+D16+D17 -> 15941 | E18: =E13+E14+E15+E16+E17 -> 16675
A20: INVESTING ACTIVITIES
A21: Capital expenditure | B21: -4880 | C21: -5095 | D21: -5714 | E21: -5638
A22: Expenditure on intangible assets | B22: -461 | C22: -266 | D22: -489 | E22: -325
A23: Acquisition of businesses, net of cash acquired | B23: -6394 | C23: -1710 | D23: -211 | E23: -809
A24: Disposal of businesses, net of cash disposed of | B24: 3530 | C24: 160 | D24: 215 | E24: -23
A25: Investments (net) in associates and joint ventures | B25: -715 | C25: -918 | D25: -582 | E25: -532
A26: Divestments in associates and joint ventures | B26: 9294 | C26: 0 | D26: 0 | E26: 0
A27: Inflows/(outflows) from treasury investments | B27: -3610 | C27: 5902 | D27: -80 | E27: -1251
A28: Other investing activities | B28: 192 | C28: 24 | D28: 665 | E28: -46
A29: Investing Cash Flow | B29: =SUM(B21:B28) -> -3044 | C29: =SUM(C21:C28) -> -1903 | D29: =SUM(D21:D28) -> -6196 | E29: =SUM(E21:E28) -> -8624
A31: FINANCING ACTIVITIES
A32: Dividend paid to shareholders of the parent | B32: -7681 | C32: -7618 | D32: -7829 | E32: -7816
A33: Dividends paid to non-controlling interests | B33: -302 | C33: -284 | D33: -323 | E33: -174
A34: Acquisition of non-controlling interests | B34: -601 | C34: -605 | D34: -52 | E34: -27
A35: Purchase of treasury shares | B35: -6548 | C35: -10679 | D35: -5234 | E35: -4678
A36: Inflows from bonds and other long-term financial debt | B36: 11339 | C36: 10936 | D36: 9806 | E36: 7992
A37: Outflows from bonds, lease liabilities and other long-term financial debt | B37: -4474 | C37: -3283 | D37: -3589 | E37: -5055
A38: Inflows/(outflows) from short-term financial debt | B38: -885 | C38: 148 | D38: -2537 | E38: 2396
A39: Financing Cash Flow | B39: =SUM(B32:B38) -> -9152 | C39: =SUM(C32:C38) -> -11385 | D39: =SUM(D32:D38) -> -9758 | E39: =SUM(E32:E38) -> -7362
A41: CASH RECONCILIATION
A42: Currency retranslations | B42: 89 | C42: -100 | D42: -682 | E42: 53
A43: Increase/(Decrease) in Cash and Cash Equivalents | B43: =B18+B29+B39+B42 -> 1757 | C43: =C18+C29+C39+C42 -> -1481 | D43: =D18+D29+D39+D42 -> -695 | E43: =E18+E29+E39+E42 -> 742
A44: Cash and cash equivalents at beginning of year | B44: 5235 | C44: 6992 | D44: 5511 | E44: 4816
...

Sheet 2. Assumptions_FY2025
A1: Nestlé — FY2025 Budget Assumptions: Adverse / Base / Favorable scenarios (full line-item detail, P&L + Cash Flow)
A3: Driver | B3: Adverse | C3: Base | D3: Favorable | E3: Source / Rationale
A4: A. INCOME STATEMENT DRIVERS
A5: Real Internal Growth (RIG) — volume/mix | B5: 0.005 | C5: 0.015 | D5: 0.025 | E5: Own split of the 3.0% organic growth assumption, using only information available on 13-Feb-2025. RIG improved from 0.1% in H1-2024 to 1.4% in H2-2024 (Full-Year Results 2024 press release), and FY2025 guidance calls for organic growth "strengthening through the year" backed by advertising & marketing spend rising toward 9% of sales. 1.5% assumes RIG holds just above its H2-2024 exit rate. Scenarios: Adverse 0.5% / Favorable 2.5% (±100 bps). Volume is the swing factor; Pricing is held at Base in all three scenarios, so Organic Growth ranges 2.0%–4.0%, spanning FY2024's actual 2.2% and a stronger recovery.
A6: Pricing | B6: =C6 -> 0.015 | C6: 0.015 | D6: =C6 -> 0.015 | E6: Own split: held at the FY2024 full-year level (1.5%). Upward pressure from coffee and cocoa cost inflation is balanced by guidance that Nestlé is "selectively investing in price as we focus on restoring competitiveness", with commodity increases offset by "accelerated delivery of cost efficiencies" (Full-Year Results 2024 press release). H2-2024 pricing had slowed to ~0.9% (organic 2.3% − RIG 1.4%).
A7: → Organic Sales Growth (RIG + Pricing) | B7: ='2. Assumptions_FY2025'!B5+'2. Assumptions_FY2025'!B6 -> 0.02 | C7: ='2. Assumptions_FY2025'!C5+'2. Assumptions_FY2025'!C6 -> 0.03 | D7: ='2. Assumptions_FY2025'!D5+'2. Assumptions_FY2025'!D6 -> 0.04 | E7: Formula: RIG + Pricing (not a separate input). Additive, per Nestlé's own definition ("OG combines Real internal growth and Pricing" — Alternative Performance Measures, Feb-2026); the small cross-effect (1.5% × 1.5% ≈ 2 bps) is ignored, consistent with how Nestlé reports its actuals. Nestlé FY2025 guidance (Full-Year Results 2024 press release, 13-Feb-2025): "organic sales growth expected to improve compared to 2024, strengthening through the year" (FY2024 organic growth was 2.2%). The resulting 3.0% is an illustrative point within that guided direction — Nestlé did not disclose a precise FY2025 organic growth number. The RIG/Pricing split was added in Step 3 without changing the 3.0% total, so the Budget figures are unchanged.
A8: Net M&A Impact | B8: =C8 -> 0 | C8: 0 | D8: =C8 -> 0 | E8: No acquisition/divestment guidance was disclosed for FY2025; assumed neutral (0.0%), consistent with FY2024's own -0.3% being a minor, non-recurring item.
A9: Foreign Exchange (FX) Impact | B9: -0.04 | C9: 0 | D9: 0.02 | E9: FY2025 guidance "assumes no significant change in key macroeconomic variables" — interpreted as a flat (0.0%) FX assumption. This is a simplifying assumption, not a forecast of currency markets. Scenarios: Adverse -4.0% / Favorable +2.0%. FX impact on Group sales was -0.9% in FY2022 and -3.7% in FY2024 (1. Segment_Data), with the Swiss franc structurally strong — so the adverse case sits near the worst recent year and the favorable case is smaller.
A10: → Implied Reported Sales Growth | B10: ='2. Assumptions_FY2025'!B7+'2. Assumptions_FY2025'!B8+'2. Assumptions_FY2025'!B9 -> -0.02 | C10: ='2. Assumptions_FY2025'!C7+'2. Assumptions_FY2025'!C8+'2. Assumptions_FY2025'!C9 -> 0.03 | D10: ='2. Assumptions_FY2025'!D7+'2. Assumptions_FY2025'!D8+'2. Assumptions_FY2025'!D9 -> 0.06 | E10: Formula: Organic Sales Growth + Net M&A Impact + FX Impact (not a separate input).
A11: Other Revenue (% of Sales) | B11: =C11 -> 0.004 | C11: 0.004 | D11: =C11 -> 0.004 | E11: Own assumption: held flat at the FY2024 ratio (366 / 91,354 = 0.40%) — an immaterial, stable line with no company guidance.
A12: Cost of Goods Sold (% of Sales) | B12: 0.539 | C12: 0.529 | D12: 0.519 | E12: Own assumption: modest improvement from FY2024's 53.3% ratio, reflecting continued procurement/input-cost savings under the "Fuel for Growth" cost-savings programme referenced in FY2025 guidance. No specific COGS-ratio guidance was disclosed. Scenarios: 53.9% / 51.9% (±100 bps). COGS ranged from 52.2% (FY2021) to 54.8% (FY2022) of sales; the range covers coffee/cocoa cost inflation versus faster Fuel for Growth savings.
A13: Distribution Expenses (% of Sales) | B13: =C13 -> 0.082 | C13: 0.082 | D13: =C13 -> 0.082 | E13: Own assumption: slight improvement from FY2024's 8.28% ratio, reflecting logistics/supply-chain efficiencies under Fuel for Growth. No specific guidance was disclosed for this line.
A14: Marketing & Administration Expenses (% of Sales) | B14: 0.214 | C14: 0.209 | D14: 0.204 | E14: Own assumption, the key driver of the guided margin step-down: FY2025 guidance states advertising & marketing spend is planned to increase toward ~9% of sales by end-2025 (from 8.1% in FY2024); this line also includes G&A, which is not separately guided, so the ratio is calibrated (from FY2024's 19.83%) so that the resulting UTOP margin lands at "or above 16.0%", per guidance — see the memo row below. Scenarios: 21.4% / 20.4% (±50 bps). Ranged 17.9%–19.9% of sales over FY2021–FY2024; reflects execution risk around the planned advertising & marketing step-up.
A15: Research & Development Costs (% of Sales) | B15: =C15 -> 0.018 | C15: 0.018 | D15: =C15 -> 0.018 | E15: Own assumption: held broadly flat versus FY2024's 1.82% ratio — Nestlé has not signalled a change in R&D investment intensity.
A16: → Resulting UTOP Margin (memo, not an input) | B16: =1+'2. Assumptions_FY2025'!B11-'2. Assumptions_FY2025'!B12-'2. Assumptions_FY2025'!B13-'2. Assumptions_FY2025'!B14-'2. Assumptions_FY2025'!B15 -> 0.151 | C16: =1+'2. Assumptions_FY2025'!C11-'2. Assumptions_FY2025'!C12-'2. Assumptions_FY2025'!C13-'2. Assumptions_FY2025'!C14-'2. Assumptions_FY2025'!C15 -> 0.166 | D16: =1+'2. Assumptions_FY2025'!D11-'2. Assumptions_FY2025'!D12-'2. Assumptions_FY2025'!D13-'2. Assumptions_FY2025'!D14-'2. Assumptions_FY2025'!D15 -> 0.181 | E16: Formula: 1 + Other Revenue% − COGS% − Distribution% − Marketing&Admin% − R&D%. Shown for reference against FY2025 guidance of "UTOP margin expected to be at or above 16.0%" (down from FY2024's 17.2%).
A17: Other Trading Items, net (% of Sales) | B17: -0.019 | C17: -0.014 | D17: -0.009 | E17: Own assumption: FY2023–FY2024 two-year average net ratio (-1.65% / -1.17%, avg ≈ -1.41%), reflecting continued but no-longer-escalating restructuring/one-off items as the prior large cost-reduction programme (2021–2022) winds down. Nestlé does not guide this line. Scenarios: -1.9% / -0.9% (±50 bps). Ranged from -3.4% (FY2021) to -1.2% (FY2024) of sales.
A18: Other Operating Items, net (% of Sales) | B18: =C18 -> -0.002 | C18: -0.002 | D18: =C18 -> -0.002 | E18: Own assumption: FY2023–FY2024 two-year average net ratio (-0.49% / +0.10%, avg ≈ -0.20%). This line is inherently one-off in nature (disposals, portfolio actions) and is not guided by the company.
A19: Financial Income Growth (vs FY2024) | B19: =C19 -> 0 | C19: 0 | D19: =C19 -> 0 | E19: Own assumption: held flat — no treasury-yield or cash-balance guidance was disclosed for FY2025.
A20: Net Financial Expense Growth (vs FY2024) | B20: 0.15 | C20: 0.05 | D20: -0.05 | E20: Own assumption (not company guidance): Nestlé's net debt rose to CHF 56.0bn at FY2024 year-end (from CHF 49.6bn a year earlier) and the company does not anticipate a new share buyback programme in 2025 — implying continued elevated net financial expenses. +5.0% growth vs FY2024's CHF 1,485m is assumed as a reasonable continuation of the FY2023→FY2024 trend (+9.2%), applied more conservatively. Financial expense is then derived as the balancing line versus the flat Financial Income assumption above. Scenarios: +15% / -5% (±10 percentage points). Net financial expense grew +19%, +31% and +9% in FY2022–FY2024 as net debt and rates rose.
A21: Income from Associates & JVs Growth | B21: -0.02 | C21: 0.08 | D21: 0.18 | E21: Own assumption: continuation of the FY2022–FY2024 recovery trend (CHF 1,040m → 1,120m → 1,249m, i.e. +7.7% then +11.5% YoY), moderated to +8.0% for FY2025. Excludes the FY2021 CHF 8,651m figure, which included the one-off L'Oréal-related gain and is not representative of a run rate. Scenarios: -2% / +18% (±10 percentage points). Grew +7.7% and +11.5% in FY2023–FY2024 (mainly L'Oréal).
A22: Effective Tax Rate | B22: 0.26 | C22: 0.24 | D22: 0.22 | E22: Own assumption: close to, but slightly below, FY2024's reported 25.0% rate, with modest normalization assumed as the one-off deferred-tax write-off that inflated the FY2024 rate is not expected to repeat. No FY2025 tax-rate guidance was disclosed. Scenarios: 26.0% / 22.0% (±200 bps). Ranged 18.2%–25.0% over FY2021–FY2024.
A23: Non-Controlling Interests (% of Profit for the Year) | B23: =C23 -> 0.026 | C23: 0.026 | D23: =C23 -> 0.026 | E23: Own assumption: held flat at the FY2024 ratio (290 / 11,174 = 2.60%) — this line has been stable (2.5%–3.4%) across FY2021–FY2024.
A24: Shares Outstanding for EPS (million) | B24: =C24 -> 2554.7 | C24: 2554.7 | D24: =C24 -> 2554.7 | E24: FY2024 weighted-average basic shares implied by reported EPS (Net Profit CHF 10,884m ÷ EPS CHF 4.19 ≈ 2,598m), reduced by the 43.5 million shares the Board proposed for cancellation in 2025. No new buyback programme is planned for 2025 per guidance, so the share count is held flat aside from that already-announced cancellation.
A26: B. CASH FLOW DRIVERS
A27: Depreciation & Amortization (% of Sales) | B27: =C27 -> 0.039 | C27: 0.039 | D27: =C27 -> 0.039 | E27: Own assumption: held flat at the FY2024 ratio (3,582 / 91,354 = 3.92%) — D&A has been stable at 3.7%–3.9% of sales across FY2021–FY2024, tracking the asset base rather than any single-year driver.
A28: Impairment (CHF m) | B28: =C28 -> 580 | C28: 580 | D28: =C28 -> 580 | E28: Own assumption: held flat at the FY2024 level, treated as a normalized run-rate figure. FY2021–FY2022 carried much larger impairments (CHF 2,614m / 2,726m) tied to a specific prior restructuring programme that has since wound down (FY2023: CHF 647m, FY2024: CHF 580m); no new large impairment is assumed.
A29: Net Disposal Result & Other Non-Cash Items (CHF m) | B29: =C29 -> 0 | C29: 0 | D29: =C29 -> 0 | E29: Own assumption: neutral placeholder. Both lines have swung between small positive and negative values FY2021–FY2024 with no discernible trend and no company guidance — modelling anything other than zero would be spurious precision.
A30: Working Capital & Other Operating Movements (CHF m) | B30: -1000 | C30: 0 | D30: 1000 | E30: Own assumption: neutral placeholder. Combined working-capital and other-operating-asset/liability movements have ranged from -CHF 3,647m (FY2022) to +CHF 874m (FY2024) with no stable trend; Nestlé gives no forward guidance on working capital, so a zero net assumption is used rather than an unsupported extrapolation. Scenarios: -CHF 1,000m / +CHF 1,000m. Ranged from -CHF 3,647m (FY2022) to +CHF 874m (FY2024).
A31: Interest Paid (% of Budgeted Financial Expense) | B31: =C31 -> 0.835 | C31: 0.835 | D31: =C31 -> 0.835 | E31: Own assumption: FY2024's historical cash-vs-accrual ratio (interest paid CHF 1,539m ÷ financial expense CHF 1,843m = 83.5%) applied to the FY2025 Budget's financial expense line.
A32: Interest Received (% of Budgeted Financial Income) | B32: =C32 -> 0.763 | C32: 0.763 | D32: =C32 -> 0.763 | E32: Own assumption: FY2024's historical ratio (interest & dividends received CHF 273m ÷ financial income CHF 358m = 76.3%) applied to the FY2025 Budget's financial income line.
A33: Taxes Paid (% of Budgeted Tax Expense) | B33: =C33 -> 0.727 | C33: 0.727 | D33: =C33 -> 0.727 | E33: Own assumption: FY2024's historical cash-vs-accrual ratio (taxes paid CHF 2,411m ÷ tax expense CHF 3,314m = 72.7%) applied to the FY2025 Budget's tax expense line, reflecting normal timing differences between accrued and cash tax.
A34: Associate Dividends Received (% of Budgeted Associate Income) | B34: =C34 -> 0.608 | C34: 0.608 | D34: =C34 -> 0.608 | E34: Own assumption: FY2024's historical ratio (dividends & interest from associates/JVs CHF 759m ÷ income from associates & JVs CHF 1,249m = 60.8%) applied to the FY2025 Budget's associate income line.
A35: Capital Expenditure (% of Sales) | B35: 0.067 | C35: 0.062 | D35: 0.057 | E35: Own assumption: continuation of the rising FY2021–FY2024 capex-intensity trend (5.6% → 5.4% → 6.1% → 6.2% of sales), held at the FY2024 level — Nestlé has not disclosed specific FY2025 capex guidance. Scenarios: 6.7% / 5.7% (±50 bps). Ranged 5.4%–6.2% of sales over FY2021–FY2024.
A36: Intangible Asset Capex (% of Sales) | B36: =C36 -> 0.004 | C36: 0.004 | D36: =C36 -> 0.004 | E36: Own assumption: four-year average ratio (0.53% / 0.28% / 0.53% / 0.36%, avg ≈ 0.42%), rounded to 0.40% of sales.
A37: Acquisitions/Disposals of Businesses, net (CHF m) | B37: =C37 -> 0 | C37: 0 | D37: =C37 -> 0 | E37: Own assumption: no acquisitions or disposals are budgeted, consistent with no M&A guidance being disclosed for FY2025 (mirrors the Net M&A Impact = 0.0% sales assumption above).
A38: Associate Investments, net (% of Sales) | B38: =C38 -> -0.006 | C38: -0.006 | D38: =C38 -> -0.006 | E38: Own assumption: continuation of the recent FY2023–FY2024 level (-CHF 582m / -CHF 532m, both ≈ -0.6% of sales), reflecting ongoing (but not accelerating) investment in associates/JVs such as coffee and pet care ventures.
A39: Divestments in Associates/JVs (CHF m) | B39: =C39 -> 0 | C39: 0 | D39: =C39 -> 0 | E39: Own assumption: zero, consistent with FY2022–FY2024 (all nil). FY2021's CHF 9,294m reflected the one-off partial disposal of Nestlé's L'Oréal stake and is not expected to recur.
A40: Treasury Investments & Other Investing (CHF m) | B40: =C40 -> 0 | C40: 0 | D40: =C40 -> 0 | E40: Own assumption: neutral placeholder. Both lines are treasury-management driven, have swung between large inflows and outflows FY2021–FY2024 (e.g. treasury investments from -CHF 3,610m to +CHF 5,902m), and are not forecastable from sales or guidance.
A41: Dividend Paid to Shareholders Growth (vs FY2024) | B41: =C41 -> 0.02 | C41: 0.02 | D41: =C41 -> 0.02 | E41: Own assumption: Nestlé has a long-standing progressive dividend policy (per-share dividend increased for over two decades); +2.0% is assumed as a modest continuation. No specific FY2025 dividend figure was available at the time of this budget (the dividend for a given year is proposed to shareholders the following February, i.e. after this budget is built).
A42: Dividends to Non-Controlling Interests (CHF m) | B42: =C42 -> -174 | C42: -174 | D42: =C42 -> -174 | E42: Own assumption: held flat at the FY2024 level. This line has ranged CHF -174m to -323m across FY2021–FY2024 with no clear trend and no guidance.
...

Sheet 2. Budget_FY2025_PL_CF
A1: Nestlé Group — FY2025 Budget (Adverse / Base / Favorable scenarios) vs FY2024 Actual, full P&L + Cash Flow detail (CHF m unless % or per-share)
A3: Metric | B3: FY2024 Actual | C3: FY2025 Budget — Adverse | D3: FY2025 Budget — Base | E3: FY2025 Budget — Favorable | F3: Base YoY Growth
A4: INCOME STATEMENT
A5: Sales | B5: ='1. Income_Statement'!E4 -> 91354 | C5: =B5*(1+'2. Assumptions_FY2025'!B10) -> 89526.92 | D5: =B5*(1+'2. Assumptions_FY2025'!C10) -> 94094.62 | E5: =B5*(1+'2. Assumptions_FY2025'!D10) -> 96835.24 | F5: =IFERROR(D5/B5-1,"") -> 0.03
A6: Other revenue | B6: ='1. Income_Statement'!E5 -> 366 | C6: =C5*'2. Assumptions_FY2025'!B11 -> 358.10768 | D6: =D5*'2. Assumptions_FY2025'!C11 -> 376.37848 | E6: =E5*'2. Assumptions_FY2025'!D11 -> 387.34096 | F6: =IFERROR(D6/B6-1,"") -> 0.028356503
A7: Cost of goods sold | B7: ='1. Income_Statement'!E6 -> -48670 | C7: =-C5*'2. Assumptions_FY2025'!B12 -> -48255.01 | D7: =-D5*'2. Assumptions_FY2025'!C12 -> -49776.054 | E7: =-E5*'2. Assumptions_FY2025'!D12 -> -50257.49 | F7: =IFERROR(D7/B7-1,"") -> 0.02272558
A8: Distribution expenses | B8: ='1. Income_Statement'!E7 -> -7567 | C8: =-C5*'2. Assumptions_FY2025'!B13 -> -7341.2074 | D8: =-D5*'2. Assumptions_FY2025'!C13 -> -7715.7588 | E8: =-E5*'2. Assumptions_FY2025'!D13 -> -7940.4897 | F8: =IFERROR(D8/B8-1,"") -> 0.019658893
A9: Marketing and administration expenses | B9: ='1. Income_Statement'!E8 -> -18112 | C9: =-C5*'2. Assumptions_FY2025'!B14 -> -19158.761 | D9: =-D5*'2. Assumptions_FY2025'!C14 -> -19665.776 | E9: =-E5*'2. Assumptions_FY2025'!D14 -> -19754.389 | F9: =IFERROR(D9/B9-1,"") -> 0.085787079
A10: Research and development costs | B10: ='1. Income_Statement'!E9 -> -1667 | C10: =-C5*'2. Assumptions_FY2025'!B15 -> -1611.4846 | D10: =-D5*'2. Assumptions_FY2025'!C15 -> -1693.7032 | E10: =-E5*'2. Assumptions_FY2025'!D15 -> -1743.0343 | F10: =IFERROR(D10/B10-1,"") -> 0.016018692
A11: Underlying Trading Operating Profit (UTOP) | B11: ='1. Income_Statement'!E10 -> 15704 | C11: =SUM(C5:C10) -> 13518.565 | D11: =SUM(D5:D10) -> 15619.707 | E11: =SUM(E5:E10) -> 17527.178 | F11: =IFERROR(D11/B11-1,"") -> -0.0053676184
A12: Other trading items, net | B12: ='1. Income_Statement'!E11+'1. Income_Statement'!E12 -> -1071 | C12: =C5*'2. Assumptions_FY2025'!B17 -> -1701.0115 | D12: =D5*'2. Assumptions_FY2025'!C17 -> -1317.3247 | E12: =E5*'2. Assumptions_FY2025'!D17 -> -871.51716 | F12: =IFERROR(D12/B12-1,"") -> 0.22999503
A13: Trading Operating Profit | B13: ='1. Income_Statement'!E13 -> 14633 | C13: =C11+C12 -> 11817.553 | D13: =D11+D12 -> 14302.382 | E13: =E11+E12 -> 16655.661 | F13: =IFERROR(D13/B13-1,"") -> -0.022593983
A14: Other operating items, net | B14: ='1. Income_Statement'!E14+'1. Income_Statement'!E15 -> 91 | C14: =C5*'2. Assumptions_FY2025'!B18 -> -179.05384 | D14: =D5*'2. Assumptions_FY2025'!C18 -> -188.18924 | E14: =E5*'2. Assumptions_FY2025'!D18 -> -193.67048 | F14: =IFERROR(D14/B14-1,"") -> -3.0680136
A15: Operating Profit | B15: ='1. Income_Statement'!E16 -> 14724 | C15: =C13+C14 -> 11638.5 | D15: =D13+D14 -> 14114.193 | E15: =E13+E14 -> 16461.991 | F15: =IFERROR(D15/B15-1,"") -> -0.041415852
A16: Financial income | B16: ='1. Income_Statement'!E17 -> 358 | C16: =B16*(1+'2. Assumptions_FY2025'!B19) -> 358 | D16: =B16*(1+'2. Assumptions_FY2025'!C19) -> 358 | E16: =B16*(1+'2. Assumptions_FY2025'!D19) -> 358 | F16: =IFERROR(D16/B16-1,"") -> 0
A17: Financial expense | B17: ='1. Income_Statement'!E18 -> -1843 | C17: =('1. Income_Statement'!E19*(1+'2. Assumptions_FY2025'!B20))-C16 -> -2065.75 | D17: =('1. Income_Statement'!E19*(1+'2. Assumptions_FY2025'!C20))-D16 -> -1917.25 | E17: =('1. Income_Statement'!E19*(1+'2. Assumptions_FY2025'!D20))-E16 -> -1768.75 | F17: =IFERROR(D17/B17-1,"") -> 0.040287575
A18: Net Financial Income/(Expense) | B18: ='1. Income_Statement'!E19 -> -1485 | C18: =C16+C17 -> -1707.75 | D18: =D16+D17 -> -1559.25 | E18: =E16+E17 -> -1410.75 | F18: =IFERROR(D18/B18-1,"") -> 0.05
A19: Profit Before Taxes, Associates and Joint Ventures | B19: ='1. Income_Statement'!E20 -> 13239 | C19: =C15+C18 -> 9930.7496 | D19: =D15+D18 -> 12554.943 | E19: =E15+E18 -> 15051.241 | F19: =IFERROR(D19/B19-1,"") -> -0.051669839
A20: Income from associates and joint ventures | B20: ='1. Income_Statement'!E21 -> 1249 | C20: =B20*(1+'2. Assumptions_FY2025'!B21) -> 1224.02 | D20: =B20*(1+'2. Assumptions_FY2025'!C21) -> 1348.92 | E20: =B20*(1+'2. Assumptions_FY2025'!D21) -> 1473.82 | F20: =IFERROR(D20/B20-1,"") -> 0.08
A21: Taxes | B21: ='1. Income_Statement'!E22 -> -3314 | C21: =-C19*'2. Assumptions_FY2025'!B22 -> -2581.9949 | D21: =-D19*'2. Assumptions_FY2025'!C22 -> -3013.1863 | E21: =-E19*'2. Assumptions_FY2025'!D22 -> -3311.273 | F21: =IFERROR(D21/B21-1,"") -> -0.090770573
A22: Profit for the Year | B22: ='1. Income_Statement'!E23 -> 11174 | C22: =C19+C20+C21 -> 8572.7747 | D22: =D19+D20+D21 -> 10890.677 | E22: =E19+E20+E21 -> 13213.788 | F22: =IFERROR(D22/B22-1,"") -> -0.025355586
A23: Of which: non-controlling interests | B23: ='1. Income_Statement'!E24 -> 290 | C23: =C22*'2. Assumptions_FY2025'!B23 -> 222.89214 | D23: =D22*'2. Assumptions_FY2025'!C23 -> 283.15759 | E23: =E22*'2. Assumptions_FY2025'!D23 -> 343.55848 | F23: =IFERROR(D23/B23-1,"") -> -0.023594505
A24: Net Profit (attributable to shareholders of the parent) | B24: ='1. Income_Statement'!E25 -> 10884 | C24: =C22-C23 -> 8349.8826 | D24: =D22-D23 -> 10607.519 | E24: =E22-E23 -> 12870.229 | F24: =IFERROR(D24/B24-1,"") -> -0.02540251
A26: UTOP Margin | B26: =IFERROR(B11/B5,"") -> 0.17190271 | C26: =IFERROR(C11/C5,"") -> 0.151 | D26: =IFERROR(D11/D5,"") -> 0.166 | E26: =IFERROR(E11/E5,"") -> 0.181
A27: Trading Operating Profit Margin | B27: =IFERROR(B13/B5,"") -> 0.16017908 | C27: =IFERROR(C13/C5,"") -> 0.132 | D27: =IFERROR(D13/D5,"") -> 0.152 | E27: =IFERROR(E13/E5,"") -> 0.172
A28: Operating Profit Margin | B28: =IFERROR(B15/B5,"") -> 0.16117521 | C28: =IFERROR(C15/C5,"") -> 0.13 | D28: =IFERROR(D15/D5,"") -> 0.15 | E28: =IFERROR(E15/E5,"") -> 0.17
A29: Net Profit Margin | B29: =IFERROR(B24/B5,"") -> 0.11914092 | C29: =IFERROR(C24/C5,"") -> 0.093266724 | D29: =IFERROR(D24/D5,"") -> 0.11273247 | E29: =IFERROR(E24/E5,"") -> 0.13290853
A30: Effective Tax Rate | B30: =IFERROR(-B21/B19,"") -> 0.25032102 | C30: =IFERROR(-C21/C19,"") -> 0.26 | D30: =IFERROR(-D21/D19,"") -> 0.24 | E30: =IFERROR(-E21/E19,"") -> 0.22
A32: Basic EPS (CHF) | B32: ='1. Income_Statement'!E33 -> 4.19 | C32: =IFERROR(C24/'2. Assumptions_FY2025'!B24,"") -> 3.2684396 | D32: =IFERROR(D24/'2. Assumptions_FY2025'!C24,"") -> 4.1521584 | E32: =IFERROR(E24/'2. Assumptions_FY2025'!D24,"") -> 5.0378633
A34: CASH FLOW STATEMENT
A35: OPERATING ACTIVITIES
A36: Operating Profit (linked from Income Statement above) | B36: ='1. Cash_Flow_Statement'!E5 -> 14724 | C36: =C15 -> 11638.5 | D36: =D15 -> 14114.193 | E36: =E15 -> 16461.991 | F36: =IFERROR(D36/B36-1,"") -> -0.041415852
A37: Depreciation and amortization | B37: ='1. Cash_Flow_Statement'!E6 -> 3582 | C37: =C5*'2. Assumptions_FY2025'!B27 -> 3491.5499 | D37: =D5*'2. Assumptions_FY2025'!C27 -> 3669.6902 | E37: =E5*'2. Assumptions_FY2025'!D27 -> 3776.5744 | F37: =IFERROR(D37/B37-1,"") -> 0.024480787
A38: Impairment | B38: ='1. Cash_Flow_Statement'!E7 -> 580 | C38: ='2. Assumptions_FY2025'!B28 -> 580 | D38: ='2. Assumptions_FY2025'!C28 -> 580 | E38: ='2. Assumptions_FY2025'!D28 -> 580 | F38: =IFERROR(D38/B38-1,"") -> 0
A39: Net disposal result & other non-cash items | B39: ='1. Cash_Flow_Statement'!E8+'1. Cash_Flow_Statement'!E9 -> -167 | C39: ='2. Assumptions_FY2025'!B29 -> 0 | D39: ='2. Assumptions_FY2025'!C29 -> 0 | E39: ='2. Assumptions_FY2025'!D29 -> 0 | F39: =IFERROR(D39/B39-1,"") -> -1
A40: Cash Flow Before Changes in Operating Assets and Liabilities | B40: ='1. Cash_Flow_Statement'!E10 -> 18719 | C40: =SUM(C36:C39) -> 15710.049 | D40: =SUM(D36:D39) -> 18363.883 | E40: =SUM(E36:E39) -> 20818.565 | F40: =IFERROR(D40/B40-1,"") -> -0.018970929
A41: Working capital & other operating movements | B41: ='1. Cash_Flow_Statement'!E11+'1. Cash_Flow_Statement'!E12 -> 874 | C41: ='2. Assumptions_FY2025'!B30 -> -1000 | D41: ='2. Assumptions_FY2025'!C30 -> 0 | E41: ='2. Assumptions_FY2025'!D30 -> 1000 | F41: =IFERROR(D41/B41-1,"") -> -1
A42: Cash Generated from Operations | B42: ='1. Cash_Flow_Statement'!E13 -> 19593 | C42: =C40+C41 -> 14710.049 | D42: =D40+D41 -> 18363.883 | E42: =E40+E41 -> 21818.565 | F42: =IFERROR(D42/B42-1,"") -> -0.062732446
A43: Interest paid | B43: ='1. Cash_Flow_Statement'!E14 -> -1539 | C43: =C17*'2. Assumptions_FY2025'!B31 -> -1724.9012 | D43: =D17*'2. Assumptions_FY2025'!C31 -> -1600.9037 | E43: =E17*'2. Assumptions_FY2025'!D31 -> -1476.9062 | F43: =IFERROR(D43/B43-1,"") -> 0.040223359
A44: Interest and dividends received | B44: ='1. Cash_Flow_Statement'!E15 -> 273 | C44: =C16*'2. Assumptions_FY2025'!B32 -> 273.154 | D44: =D16*'2. Assumptions_FY2025'!C32 -> 273.154 | E44: =E16*'2. Assumptions_FY2025'!D32 -> 273.154 | F44: =IFERROR(D44/B44-1,"") -> 0.00056410256
...

Sheet 3. Variance_Analysis
A1: Nestlé Group — FY2025 Budget vs FY2025 Actual — Variance Analysis (CHF m unless % or per-share)
A3: A. GROUP SALES GROWTH BRIDGE — FY2025 BUDGET VS ACTUAL (RIG / PRICING SPLIT)
A5: Component | B5: FY2025 Budget (Base) | C5: FY2025 Actual | D5: Variance (bps)
A6: Real Internal Growth (RIG) | B6: ='2. Assumptions_FY2025'!C5 -> 0.015 | C6: 0.008 | D6: =(C6-B6)*10000 -> -70
A7: Pricing | B7: ='2. Assumptions_FY2025'!C6 -> 0.015 | C7: 0.028 | D7: =(C7-B7)*10000 -> 130
A8: Organic Growth | B8: ='2. Assumptions_FY2025'!C7 -> 0.03 | C8: 0.035 | D8: =(C8-B8)*10000 -> 50
A9: Net M&A Impact | B9: ='2. Assumptions_FY2025'!C8 -> 0 | C9: 0.001 | D9: =(C9-B9)*10000 -> 10
A10: Foreign Exchange (FX) Impact | B10: ='2. Assumptions_FY2025'!C9 -> 0 | C10: -0.057 | D10: =(C10-B10)*10000 -> -570
A11: Reported Sales Growth | B11: =B8+B9+B10 -> 0.03 | C11: =C16/'2. Budget_FY2025_PL_CF'!B5-1 -> -0.020404142 | D11: =(C11-B11)*10000 -> -504.04142
A12: RIG, Pricing, Organic Growth, Net M&A and FX are Nestlé's own disclosed figures, each rounded to 0.1 percentage point, so they do not sum exactly; FY2025 Actual Reported Sales Growth is calculated directly from the Sales lines (Section B).
A14: B. FULL INCOME STATEMENT VARIANCE — FY2025 BUDGET VS ACTUAL (CHF m)
A15: Metric | B15: FY2025 Budget (Base) | C15: FY2025 Actual | D15: Variance (CHF m) | E15: Variance (%)
A16: Sales | B16: ='2. Budget_FY2025_PL_CF'!D5 -> 94094.62 | C16: 89490 | D16: =C16-B16 -> -4604.62 | E16: =IFERROR(C16/B16-1,"") -> -0.04893606
A17: Other revenue | B17: ='2. Budget_FY2025_PL_CF'!D6 -> 376.37848 | C17: 395 | D17: =C17-B17 -> 18.62152 | E17: =IFERROR(C17/B17-1,"") -> 0.049475517
A18: Cost of goods sold | B18: ='2. Budget_FY2025_PL_CF'!D7 -> -49776.054 | C18: -48694 | D18: =C18-B18 -> 1082.054 | E18: =IFERROR(C18/B18-1,"") -> -0.021738444
A19: Distribution expenses | B19: ='2. Budget_FY2025_PL_CF'!D8 -> -7715.7588 | C19: -7306 | D19: =C19-B19 -> 409.75884 | E19: =IFERROR(C19/B19-1,"") -> -0.053106745
A20: Marketing and administration expenses | B20: ='2. Budget_FY2025_PL_CF'!D9 -> -19665.776 | C20: -17883 | D20: =C20-B20 -> 1782.7756 | E20: =IFERROR(C20/B20-1,"") -> -0.090653713
A21: Research and development costs | B21: ='2. Budget_FY2025_PL_CF'!D10 -> -1693.7032 | C21: -1613 | D21: =C21-B21 -> 80.70316 | E21: =IFERROR(C21/B21-1,"") -> -0.04764894
A22: Underlying Trading Operating Profit (UTOP) | B22: ='2. Budget_FY2025_PL_CF'!D11 -> 15619.707 | C22: =SUM(C16:C21) -> 14389 | D22: =C22-B22 -> -1230.7069 | E22: =IFERROR(C22/B22-1,"") -> -0.078791934
A23: Other trading items, net | B23: ='2. Budget_FY2025_PL_CF'!D12 -> -1317.3247 | C23: -1714 | D23: =C23-B23 -> -396.67532 | E23: =IFERROR(C23/B23-1,"") -> 0.30112191
A24: Trading Operating Profit | B24: ='2. Budget_FY2025_PL_CF'!D13 -> 14302.382 | C24: =C22+C23 -> 12675 | D24: =C24-B24 -> -1627.3822 | E24: =IFERROR(C24/B24-1,"") -> -0.113784
A25: Other operating items, net | B25: ='2. Budget_FY2025_PL_CF'!D14 -> -188.18924 | C25: -398 | D25: =C25-B25 -> -209.81076 | E25: =IFERROR(C25/B25-1,"") -> 1.1148924
A26: Operating Profit | B26: ='2. Budget_FY2025_PL_CF'!D15 -> 14114.193 | C26: =C24+C25 -> 12277 | D26: =C26-B26 -> -1837.193 | E26: =IFERROR(C26/B26-1,"") -> -0.13016635
A27: Financial income | B27: ='2. Budget_FY2025_PL_CF'!D16 -> 358 | C27: 300 | D27: =C27-B27 -> -58 | E27: =IFERROR(C27/B27-1,"") -> -0.16201117
A28: Financial expense | B28: ='2. Budget_FY2025_PL_CF'!D17 -> -1917.25 | C28: -1826 | D28: =C28-B28 -> 91.25 | E28: =IFERROR(C28/B28-1,"") -> -0.04759421
A29: Net Financial Income/(Expense) | B29: ='2. Budget_FY2025_PL_CF'!D18 -> -1559.25 | C29: =C27+C28 -> -1526 | D29: =C29-B29 -> 33.25 | E29: =IFERROR(C29/B29-1,"") -> -0.021324355
A30: Profit Before Taxes, Associates and Joint Ventures | B30: ='2. Budget_FY2025_PL_CF'!D19 -> 12554.943 | C30: =C26+C29 -> 10751 | D30: =C30-B30 -> -1803.943 | E30: =IFERROR(C30/B30-1,"") -> -0.14368389
A31: Income from associates and joint ventures | B31: ='2. Budget_FY2025_PL_CF'!D20 -> 1348.92 | C31: 1143 | D31: =C31-B31 -> -205.92 | E31: =IFERROR(C31/B31-1,"") -> -0.15265546
A32: Taxes | B32: ='2. Budget_FY2025_PL_CF'!D21 -> -3013.1863 | C32: -2640 | D32: =C32-B32 -> 373.18632 | E32: =IFERROR(C32/B32-1,"") -> -0.12385106
A33: Profit for the Year | B33: ='2. Budget_FY2025_PL_CF'!D22 -> 10890.677 | C33: =C30+C31+C32 -> 9254 | D33: =C33-B33 -> -1636.6767 | E33: =IFERROR(C33/B33-1,"") -> -0.15028237
A34: Of which: non-controlling interests | B34: ='2. Budget_FY2025_PL_CF'!D23 -> 283.15759 | C34: 221 | D34: =C34-B34 -> -62.157594 | E34: =IFERROR(C34/B34-1,"") -> -0.2195159
A35: Net Profit (attributable to shareholders of the parent) | B35: ='2. Budget_FY2025_PL_CF'!D24 -> 10607.519 | C35: =C33-C34 -> 9033 | D35: =C35-B35 -> -1574.5191 | E35: =IFERROR(C35/B35-1,"") -> -0.14843424
A37: UTOP Margin | B37: =IFERROR(B22/B16,"") -> 0.166 | C37: =IFERROR(C22/C16,"") -> 0.16078891 | D37: =(C37-B37)*10000 -> -52.11085
A38: Trading Operating Profit Margin | B38: =IFERROR(B24/B16,"") -> 0.152 | C38: =IFERROR(C24/C16,"") -> 0.14163594 | D38: =(C38-B38)*10000 -> -103.64063
A39: Operating Profit Margin | B39: =IFERROR(B26/B16,"") -> 0.15 | C39: =IFERROR(C26/C16,"") -> 0.13718851 | D39: =(C39-B39)*10000 -> -128.11487
A40: Net Profit Margin | B40: =IFERROR(B35/B16,"") -> 0.11273247 | C40: =IFERROR(C35/C16,"") -> 0.10093865 | D40: =(C40-B40)*10000 -> -117.93819
A41: Effective Tax Rate | B41: =IFERROR(-B32/B30,"") -> 0.24 | C41: =IFERROR(-C32/C30,"") -> 0.24555855 | D41: =(C41-B41)*10000 -> 55.585527
A43: Basic EPS (CHF) | B43: ='2. Budget_FY2025_PL_CF'!D32 -> 4.1521584 | C43: 3.51 | D43: =C43-B43 -> -0.64215841 | E43: =IFERROR(C43/B43-1,"") -> -0.15465653
A45: "Other trading items, net" and "Other operating items, net" are shown net for FY2025 Actual (row 23: other trading income 135 − other trading expenses 1,849; row 25: other operating income 253 − other operating expenses 651), matching the combined-net convention already used for these lines in 2. Budget_FY2025_PL_CF.
A47: C. FULL CASH FLOW VARIANCE — FY2025 BUDGET VS ACTUAL (CHF m)
...

Sheet 4. Assumptions_FY2026
A1: Nestlé — FY2026 Reforecast Assumptions (full year, as of 23-Jul-2026)
A2: Where Nestlé has guided a number (latest: Half-Year Results 2026, 23-Jul-2026), the reforecast uses it. Everything else is a judgement informed by the FY2025 variance and the H1-2026 actuals, never a copy of FY2025.
A3: Driver | B3: FY2025 Budget (Base) | C3: FY2025 Actual | D3: FY2026 Reforecast | E3: H1-2026 Actual | F3: Source / rationale
A4: A. INCOME STATEMENT DRIVERS
A5: Real Internal Growth (RIG) | B5: ='2. Assumptions_FY2025'!C5 -> 0.015 | C5: ='3. Variance_Analysis'!C6 -> 0.008 | D5: 0.016 | E5: 0.015 | F5: [Judgement] Guidance (23-Jul-2026): RIG "accelerating versus 2025" (0.8%). H1-2026 RIG was 1.5% (Q1 1.2%, Q2 1.8%) and the infant-formula recall drag is fading (-90 bps on OG in Q1, -30 bps in Q2): 1.6% for the year. The FY2025 budget over-estimated volume (1.5% vs 0.8%), so this stays below the Q2 run-rate.
A6: Pricing | B6: ='2. Assumptions_FY2025'!C6 -> 0.015 | C6: ='3. Variance_Analysis'!C7 -> 0.028 | D6: 0.019 | E6: 0.021 | F6: [Judgement] The FY2025 budget under-estimated pricing by 130 bps. Pricing is now easing as coffee and cocoa costs fall (Q1-2026 2.3%, Q2 1.9%), so 1.9% for the year.
